<mujocoinclude>
    <light cutoff="100" diffuse="1 1 1" dir="-0 0 -1.3" directional="true" exponent="1" pos="0 0 1.3" specular=".1 .1 .1"/>
    <geom conaffinity="1" condim="3" name="floor" pos="0 0 0" rgba="0.8 0.9 0.8 1" size="40 40 40" type="plane" material="MatPlane"/>
    <body name="torso" pos="0 0 1.25">
      <camera name="track" mode="trackcom" pos="0 -3 1" xyaxes="1 0 0 0 0 1"/>
      <joint armature="0" axis="1 0 0" damping="0" limited="false" name="rootx" pos="0 0 0" stiffness="0" type="slide"/>
      <joint armature="0" axis="0 0 1" damping="0" limited="false" name="rootz" pos="0 0 0" ref="1.25" stiffness="0" type="slide"/>
      <joint armature="0" axis="0 1 0" damping="0" limited="false" name="rooty" pos="0 0 1.25" stiffness="0" type="hinge"/>
      <geom friction="0.9" fromto="0 0 1.45 0 0 1.05" name="torso_geom" size="0.05" type="capsule"/>
      <body name="thigh_right" pos="0 0 1.05">
        <joint axis="0 -1 0" name="thigh_right_joint" pos="0 0 1.05" range="-150 0" type="hinge"/>
        <geom friction="0.9" fromto="0 0 1.05 0 0 0.6" name="thigh_geom" size="0.05" type="capsule"/>
        <body name="leg_right" pos="0 0 0.35">
          <joint axis="0 -1 0" name="leg_right_joint" pos="0 0 0.6" range="-150 0" type="hinge"/>
          <geom friction="0.9" fromto="0 0 0.6 0 0 0.1" name="leg_geom" size="0.04" type="capsule"/>
          <body name="foot_right" pos="0.2/2 0 0.1">
            <joint axis="0 -1 0" name="foot_right_joint" pos="0 0 0.1" range="-45 45" type="hinge"/>
            <geom friction="0.9" fromto="-0.0 0 0.1 0.2 0 0.1" name="foot_geom" size="0.06" type="capsule"/>
          </body>
        </body>
      </body>
      <body name="thigh_left" pos="0 0 1.05">
        <joint axis="0 -1 0" name="thigh_left_joint" pos="0 0 1.05" range="-150 0" type="hinge"/>
        <geom friction="0.9" fromto="0 0 1.05 0 0 0.6" name="thigh_left_geom" rgba=".7 .3 .6 1" size="0.05" type="capsule"/>
        <body name="leg_left" pos="0 0 0.35">
          <joint axis="0 -1 0" name="leg_left_joint" pos="0 0 0.6" range="-150 0" type="hinge"/>
          <geom friction="0.9" fromto="0 0 0.6 0 0 0.1" name="leg_left_geom" rgba=".7 .3 .6 1" size="0.04" type="capsule"/>
          <body name="foot_left" pos="0.2/2 0 0.1">
            <joint axis="0 -1 0" name="foot_left_joint" pos="0 0 0.1" range="-45 45" type="hinge"/>
            <geom friction="0.9" fromto="-0.0 0 0.1 0.2 0 0.1" name="foot_left_geom" rgba=".7 .3 .6 1" size="0.06" type="capsule"/>
          </body>
        </body>
      </body>
    </body>

    <!-- <body name="gtorso" pos="0 0 1.25">
      <geom friction="0.9" fromto="1 0 1.45 1 0 1.05" name="gtorso_geom" size="0.05" type="capsule" rgba="0 1 0 0.3"/>
      <body name="gthigh_right" pos="0 0 1.05">
        <geom friction="0.9" fromto="1 0 1.05 1 0 0.6" name="gthigh_geom" size="0.05" type="capsule" rgba="0 1 0 0.3"/>
        <body name="gleg_right" pos="0 0 0.35">
          <geom friction="0.9" fromto="1 0 0.6 1 0 0.1" name="gleg_geom" size="0.04" type="capsule" rgba="0 1 0 0.3"/>
          <body name="gfoot_right" pos="0.2/2 0 0.1">
            <geom friction="0.9" fromto="1 0 0.1 1.2 0 0.1" name="gfoot_geom" size="0.06" type="capsule" rgba="0 1 0 0.3"/>
          </body>
        </body>
      </body>
      <body name="gthigh_left" pos="0 0 1.05">
        <geom friction="0.9" fromto="1 0 1.05 1 0 0.6" name="gthigh_left_geom" size="0.05" type="capsule" rgba="0 1 0 0.3"/>
        <body name="gleg_left" pos="1 0 0.35">
          <geom friction="0.9" fromto="1 0 0.6 1 0 0.1" name="gleg_left_geom" size="0.04" type="capsule" rgba="0 1 0 0.3"/>
          <body name="gfoot_left" pos="0.2/2 0 0.1">
            <geom friction="0.9" fromto="1 0 0.1 1.2 0 0.1" name="gfoot_left_geom" size="0.06" type="capsule" rgba="0 1 0 0.3"/>
          </body>
        </body>
      </body>
    </body> -->
</mujocoinclude>
