<mujocoinclude>
  <body name="torso" pos="0 0 1.21">
    <joint armature="0" axis="1 0 0" damping="0" limited="false" name="rootx" pos="0 0 -1.25" type="slide" />
    <joint armature="0" axis="0 0 1" damping="0" limited="false" name="rootz" pos="0 0 -1.25" ref="1.25" type="slide" />
    <joint armature="0" axis="0 1 0" damping="0" limited="false" name="rooty" pos="0 0 0" />
    <geom friction="0.9 0.1 0.1" name="torso_geom" size="0.05 0.2" type="capsule" />
    <camera mode="trackcom" name="track" pos="0 -3 -0.25" quat="0.707107 0.707107 0 0" />
    <body name="thigh_right" pos="0 0 -0.2">
      <joint axis="0 -1 0" name="thigh_right_joint" pos="0 0 0" range="-2.61799 0" />
      <geom friction="0.9 0.1 0.1" name="thigh_geom" pos="0 0 -0.225" size="0.05 0.225" type="capsule" />
      <body name="leg_right" pos="0 0 -0.7">
          <joint axis="0 -1 0" name="leg_right_joint" pos="0 0 0.25" range="-2.61799 0" />
          <geom friction="0.9 0.1 0.1" name="leg_geom" size="0.04 0.25" type="capsule" />
          <body name="foot_right" pos="0.2 0 -0.35">
            <joint axis="0 -1 0" name="foot_right_joint" pos="-0.2 0 0.1" range="-0.785398 0.785398" />
            <geom friction="0.9 0.1 0.1" name="foot_geom" pos="-0.1 0 0.1" quat="0.707107 0 -0.707107 0" size="0.06 0.1" type="capsule" />
          </body>
      </body>
    </body>
    <body name="thigh_left" pos="0 0 -0.2">
      <joint axis="0 -1 0" name="thigh_left_joint" pos="0 0 0" range="-2.61799 0" />
      <geom friction="0.9 0.1 0.1" name="thigh_left_geom" pos="0 0 -0.225" rgba="0.7 0.3 0.6 1" size="0.05 0.225" type="capsule" />
      <body name="leg_left" pos="0 0 -0.7">
        <joint axis="0 -1 0" name="leg_left_joint" pos="0 0 0.25" range="-2.61799 0" />
        <geom friction="0.9 0.1 0.1" name="leg_left_geom" rgba="0.7 0.3 0.6 1" size="0.04 0.25" type="capsule" />
        <body name="foot_left" pos="0.2 0 -0.35">
          <joint axis="0 -1 0" name="foot_left_joint" pos="-0.2 0 0.1" range="-0.785398 0.785398" />
          <geom friction="0.9 0.1 0.1" name="foot_left_geom" pos="-0.1 0 0.1" quat="0.707107 0 -0.707107 0" rgba="0.7 0.3 0.6 1" size="0.06 0.1" type="capsule" />
        </body>
      </body>
    </body>
  </body>
  <body name="gtorso" pos="1.5 0 1.21">
    <geom friction="0.9 0.1 0.1" name="gtorso_geom" rgba="0 1 0 0.3" size="0.05 0.2" type="capsule" />
    <body name="gthigh_right" pos="-1 0 -0.2">
      <geom friction="0.9 0.1 0.1" name="gthigh_geom" pos="1 0 -0.225" rgba="0 1 0 0.3" size="0.05 0.225" type="capsule" />
      <body name="gleg_right" pos="0 0 -0.7">
        <geom friction="0.9 0.1 0.1" name="gleg_geom" pos="1 0 0" rgba="0 1 0 0.3" size="0.04 0.25" type="capsule" />
        <body name="gfoot_right" pos="0.2 0 -0.35">
          <geom friction="0.9 0.1 0.1" name="gfoot_geom" pos="0.9 0 0.1" quat="0.707107 0 -0.707107 0" rgba="0 1 0 0.3" size="0.06 0.1" type="capsule" />
        </body>
      </body>
    </body>
    <body name="gthigh_left" pos="-1 0 -0.2">
      <geom friction="0.9 0.1 0.1" name="gthigh_left_geom" pos="1 0 -0.225" rgba="0 1 0 0.3" size="0.05 0.225" type="capsule" />
      <body name="gleg_left" pos="1 0 -0.7">
        <geom friction="0.9 0.1 0.1" name="gleg_left_geom" rgba="0 1 0 0.3" size="0.04 0.25" type="capsule" />
        <body name="gfoot_left" pos="-0.8 0 -0.35">
          <geom friction="0.9 0.1 0.1" name="gfoot_left_geom" pos="0.9 0 0.1" quat="0.707107 0 -0.707107 0" rgba="0 1 0 0.3" size="0.06 0.1" type="capsule" />
        </body>
      </body>
    </body>
  </body>
</mujocoinclude>
